time 0ms: Simulator started for FCFS [Q <empty>]
time 0ms: Process A arrived and added to ready queue [Q A]
time 0ms: Process B arrived and added to ready queue [Q A B]
time 0ms: Process C arrived and added to ready queue [Q A B C]
time 0ms: Process X arrived and added to ready queue [Q A B C X]
time 0ms: Process Y arrived and added to ready queue [Q A B C X Y]
time 0ms: Process Z arrived and added to ready queue [Q A B C X Y Z]
time 4ms: Process A started using the CPU [Q B C X Y Z]
time 104ms: Process A completed a CPU burst; 3 bursts to go [Q B C X Y Z]
time 104ms: Process A switching out of CPU; will block on I/O until time 308ms [Q B C X Y Z]
time 112ms: Process B started using the CPU [Q C X Y Z]
time 213ms: Process B completed a CPU burst; 3 bursts to go [Q C X Y Z]
time 213ms: Process B switching out of CPU; will block on I/O until time 417ms [Q C X Y Z]
time 221ms: Process C started using the CPU [Q X Y Z]
time 308ms: Process A completed I/O; added to ready queue [Q X Y Z A]
time 323ms: Process C completed a CPU burst; 3 bursts to go [Q X Y Z A]
time 323ms: Process C switching out of CPU; will block on I/O until time 527ms [Q X Y Z A]
time 331ms: Process X started using the CPU [Q Y Z A]
time 417ms: Process B completed I/O; added to ready queue [Q Y Z A B]
time 434ms: Process X completed a CPU burst; 3 bursts to go [Q Y Z A B]
time 434ms: Process X switching out of CPU; will block on I/O until time 638ms [Q Y Z A B]
time 442ms: Process Y started using the CPU [Q Z A B]
time 527ms: Process C completed I/O; added to ready queue [Q Z A B C]
time 546ms: Process Y completed a CPU burst; 3 bursts to go [Q Z A B C]
time 546ms: Process Y switching out of CPU; will block on I/O until time 750ms [Q Z A B C]
time 554ms: Process Z started using the CPU [Q A B C]
time 638ms: Process X completed I/O; added to ready queue [Q A B C X]
time 659ms: Process Z completed a CPU burst; 3 bursts to go [Q A B C X]
time 659ms: Process Z switching out of CPU; will block on I/O until time 863ms [Q A B C X]
time 667ms: Process A started using the CPU [Q B C X]
time 750ms: Process Y completed I/O; added to ready queue [Q B C X Y]
time 767ms: Process A completed a CPU burst; 2 bursts to go [Q B C X Y]
time 767ms: Process A switching out of CPU; will block on I/O until time 971ms [Q B C X Y]
time 775ms: Process B started using the CPU [Q C X Y]
time 863ms: Process Z completed I/O; added to ready queue [Q C X Y Z]
time 876ms: Process B completed a CPU burst; 2 bursts to go [Q C X Y Z]
time 876ms: Process B switching out of CPU; will block on I/O until time 1080ms [Q C X Y Z]
time 884ms: Process C started using the CPU [Q X Y Z]
time 971ms: Process A completed I/O; added to ready queue [Q X Y Z A]
time 986ms: Process C completed a CPU burst; 2 bursts to go [Q X Y Z A]
time 986ms: Process C switching out of CPU; will block on I/O until time 1190ms [Q X Y Z A]
time 994ms: Process X started using the CPU [Q Y Z A]
time 1080ms: Process B completed I/O; added to ready queue [Q Y Z A B]
time 1097ms: Process X completed a CPU burst; 2 bursts to go [Q Y Z A B]
time 1097ms: Process X switching out of CPU; will block on I/O until time 1301ms [Q Y Z A B]
time 1105ms: Process Y started using the CPU [Q Z A B]
time 1190ms: Process C completed I/O; added to ready queue [Q Z A B C]
time 1209ms: Process Y completed a CPU burst; 2 bursts to go [Q Z A B C]
time 1209ms: Process Y switching out of CPU; will block on I/O until time 1413ms [Q Z A B C]
time 1217ms: Process Z started using the CPU [Q A B C]
time 1301ms: Process X completed I/O; added to ready queue [Q A B C X]
time 1322ms: Process Z completed a CPU burst; 2 bursts to go [Q A B C X]
time 1322ms: Process Z switching out of CPU; will block on I/O until time 1526ms [Q A B C X]
time 1330ms: Process A started using the CPU [Q B C X]
time 1413ms: Process Y completed I/O; added to ready queue [Q B C X Y]
time 1430ms: Process A completed a CPU burst; 1 burst to go [Q B C X Y]
time 1430ms: Process A switching out of CPU; will block on I/O until time 1634ms [Q B C X Y]
time 1438ms: Process B started using the CPU [Q C X Y]
time 1526ms: Process Z completed I/O; added to ready queue [Q C X Y Z]
time 1539ms: Process B completed a CPU burst; 1 burst to go [Q C X Y Z]
time 1539ms: Process B switching out of CPU; will block on I/O until time 1743ms [Q C X Y Z]
time 1547ms: Process C started using the CPU [Q X Y Z]
time 1634ms: Process A completed I/O; added to ready queue [Q X Y Z A]
time 1649ms: Process C completed a CPU burst; 1 burst to go [Q X Y Z A]
time 1649ms: Process C switching out of CPU; will block on I/O until time 1853ms [Q X Y Z A]
time 1657ms: Process X started using the CPU [Q Y Z A]
time 1743ms: Process B completed I/O; added to ready queue [Q Y Z A B]
time 1760ms: Process X completed a CPU burst; 1 burst to go [Q Y Z A B]
time 1760ms: Process X switching out of CPU; will block on I/O until time 1964ms [Q Y Z A B]
time 1768ms: Process Y started using the CPU [Q Z A B]
time 1853ms: Process C completed I/O; added to ready queue [Q Z A B C]
time 1872ms: Process Y completed a CPU burst; 1 burst to go [Q Z A B C]
time 1872ms: Process Y switching out of CPU; will block on I/O until time 2076ms [Q Z A B C]
time 1880ms: Process Z started using the CPU [Q A B C]
time 1964ms: Process X completed I/O; added to ready queue [Q A B C X]
time 1985ms: Process Z completed a CPU burst; 1 burst to go [Q A B C X]
time 1985ms: Process Z switching out of CPU; will block on I/O until time 2189ms [Q A B C X]
time 1993ms: Process A started using the CPU [Q B C X]
time 2076ms: Process Y completed I/O; added to ready queue [Q B C X Y]
time 2093ms: Process A terminated [Q B C X Y]
time 2101ms: Process B started using the CPU [Q C X Y]
time 2189ms: Process Z completed I/O; added to ready queue [Q C X Y Z]
time 2202ms: Process B terminated [Q C X Y Z]
time 2210ms: Process C started using the CPU [Q X Y Z]
time 2312ms: Process C terminated [Q X Y Z]
time 2320ms: Process X started using the CPU [Q Y Z]
time 2423ms: Process X terminated [Q Y Z]
time 2431ms: Process Y started using the CPU [Q Z]
time 2535ms: Process Y terminated [Q Z]
time 2543ms: Process Z started using the CPU [Q <empty>]
time 2648ms: Process Z terminated [Q <empty>]
time 2652ms: Simulator ended for FCFS


time 0ms: Simulator started for SRT [Q <empty>]
time 0ms: Process A arrived and added to ready queue [Q A]
time 0ms: Process B arrived and added to ready queue [Q A B]
time 0ms: Process C arrived and added to ready queue [Q A B C]
time 0ms: Process X arrived and added to ready queue [Q A B C X]
time 0ms: Process Y arrived and added to ready queue [Q A B C X Y]
time 0ms: Process Z arrived and added to ready queue [Q A B C X Y Z]
time 4ms: Process A started using the CPU [Q B C X Y Z]
time 104ms: Process A completed a CPU burst; 3 bursts to go [Q B C X Y Z]
time 104ms: Process A switching out of CPU; will block on I/O until time 308ms [Q B C X Y Z]
time 112ms: Process B started using the CPU [Q C X Y Z]
time 213ms: Process B completed a CPU burst; 3 bursts to go [Q C X Y Z]
time 213ms: Process B switching out of CPU; will block on I/O until time 417ms [Q C X Y Z]
time 221ms: Process C started using the CPU [Q X Y Z]
time 308ms: Process A completed I/O; added to ready queue [Q A X Y Z]
time 323ms: Process C completed a CPU burst; 3 bursts to go [Q A X Y Z]
time 323ms: Process C switching out of CPU; will block on I/O until time 527ms [Q A X Y Z]
time 331ms: Process A started using the CPU [Q X Y Z]
time 417ms: Process B completed I/O; added to ready queue [Q B X Y Z]
time 431ms: Process A completed a CPU burst; 2 bursts to go [Q B X Y Z]
time 431ms: Process A switching out of CPU; will block on I/O until time 635ms [Q B X Y Z]
time 439ms: Process B started using the CPU [Q X Y Z]
time 527ms: Process C completed I/O; added to ready queue [Q C X Y Z]
time 540ms: Process B completed a CPU burst; 2 bursts to go [Q C X Y Z]
time 540ms: Process B switching out of CPU; will block on I/O until time 744ms [Q C X Y Z]
time 548ms: Process C started using the CPU [Q X Y Z]
time 635ms: Process A completed I/O; added to ready queue [Q A X Y Z]
time 650ms: Process C completed a CPU burst; 2 bursts to go [Q A X Y Z]
time 650ms: Process C switching out of CPU; will block on I/O until time 854ms [Q A X Y Z]
time 658ms: Process A started using the CPU [Q X Y Z]
time 744ms: Process B completed I/O; added to ready queue [Q B X Y Z]
time 758ms: Process A completed a CPU burst; 1 burst to go [Q B X Y Z]
time 758ms: Process A switching out of CPU; will block on I/O until time 962ms [Q B X Y Z]
time 766ms: Process B started using the CPU [Q X Y Z]
time 854ms: Process C completed I/O; added to ready queue [Q C X Y Z]
time 867ms: Process B completed a CPU burst; 1 burst to go [Q C X Y Z]
time 867ms: Process B switching out of CPU; will block on I/O until time 1071ms [Q C X Y Z]
time 875ms: Process C started using the CPU [Q X Y Z]
time 962ms: Process A completed I/O; added to ready queue [Q A X Y Z]
time 977ms: Process C completed a CPU burst; 1 burst to go [Q A X Y Z]
time 977ms: Process C switching out of CPU; will block on I/O until time 1181ms [Q A X Y Z]
time 985ms: Process A started using the CPU [Q X Y Z]
time 1071ms: Process B completed I/O; added to ready queue [Q B X Y Z]
time 1085ms: Process A terminated [Q B X Y Z]
time 1093ms: Process B started using the CPU [Q X Y Z]
time 1181ms: Process C completed I/O; added to ready queue [Q C X Y Z]
time 1194ms: Process B terminated [Q C X Y Z]
time 1202ms: Process C started using the CPU [Q X Y Z]
time 1304ms: Process C terminated [Q X Y Z]
time 1312ms: Process X started using the CPU [Q Y Z]
time 1415ms: Process X completed a CPU burst; 3 bursts to go [Q Y Z]
time 1415ms: Process X switching out of CPU; will block on I/O until time 1619ms [Q Y Z]
time 1423ms: Process Y started using the CPU [Q Z]
time 1527ms: Process Y completed a CPU burst; 3 bursts to go [Q Z]
time 1527ms: Process Y switching out of CPU; will block on I/O until time 1731ms [Q Z]
time 1535ms: Process Z started using the CPU [Q <empty>]
time 1619ms: Process X completed I/O; added to ready queue [Q X]
time 1640ms: Process Z completed a CPU burst; 3 bursts to go [Q X]
time 1640ms: Process Z switching out of CPU; will block on I/O until time 1844ms [Q X]
time 1648ms: Process X started using the CPU [Q <empty>]
time 1731ms: Process Y completed I/O; added to ready queue [Q Y]
time 1751ms: Process X completed a CPU burst; 2 bursts to go [Q Y]
time 1751ms: Process X switching out of CPU; will block on I/O until time 1955ms [Q Y]
time 1759ms: Process Y started using the CPU [Q <empty>]
time 1844ms: Process Z completed I/O; added to ready queue [Q Z]
time 1863ms: Process Y completed a CPU burst; 2 bursts to go [Q Z]
time 1863ms: Process Y switching out of CPU; will block on I/O until time 2067ms [Q Z]
time 1871ms: Process Z started using the CPU [Q <empty>]
time 1955ms: Process X completed I/O; added to ready queue [Q X]
time 1976ms: Process Z completed a CPU burst; 2 bursts to go [Q X]
time 1976ms: Process Z switching out of CPU; will block on I/O until time 2180ms [Q X]
time 1984ms: Process X started using the CPU [Q <empty>]
time 2067ms: Process Y completed I/O; added to ready queue [Q Y]
time 2087ms: Process X completed a CPU burst; 1 burst to go [Q Y]
time 2087ms: Process X switching out of CPU; will block on I/O until time 2291ms [Q Y]
time 2095ms: Process Y started using the CPU [Q <empty>]
time 2180ms: Process Z completed I/O; added to ready queue [Q Z]
time 2199ms: Process Y completed a CPU burst; 1 burst to go [Q Z]
time 2199ms: Process Y switching out of CPU; will block on I/O until time 2403ms [Q Z]
time 2207ms: Process Z started using the CPU [Q <empty>]
time 2291ms: Process X completed I/O; added to ready queue [Q X]
time 2312ms: Process Z completed a CPU burst; 1 burst to go [Q X]
time 2312ms: Process Z switching out of CPU; will block on I/O until time 2516ms [Q X]
time 2320ms: Process X started using the CPU [Q <empty>]
time 2403ms: Process Y completed I/O; added to ready queue [Q Y]
time 2423ms: Process X terminated [Q Y]
time 2431ms: Process Y started using the CPU [Q <empty>]
time 2516ms: Process Z completed I/O; added to ready queue [Q Z]
time 2535ms: Process Y terminated [Q Z]
time 2543ms: Process Z started using the CPU [Q <empty>]
time 2648ms: Process Z terminated [Q <empty>]
time 2652ms: Simulator ended for SRT


time 0ms: Simulator started for RR [Q <empty>]
time 0ms: Process A arrived and added to ready queue [Q A]
time 0ms: Process B arrived and added to ready queue [Q A B]
time 0ms: Process C arrived and added to ready queue [Q A B C]
time 0ms: Process X arrived and added to ready queue [Q A B C X]
time 0ms: Process Y arrived and added to ready queue [Q A B C X Y]
time 0ms: Process Z arrived and added to ready queue [Q A B C X Y Z]
time 4ms: Process A started using the CPU [Q B C X Y Z]
time 88ms: Time slice expired; process A preempted with 20ms to go [Q B C X Y Z]
time 92ms: Process B started using the CPU [Q C X Y Z A]
time 176ms: Time slice expired; process B preempted with 21ms to go [Q C X Y Z A]
time 180ms: Process C started using the CPU [Q X Y Z A B]
time 264ms: Time slice expired; process C preempted with 22ms to go [Q X Y Z A B]
time 268ms: Process X started using the CPU [Q Y Z A B C]
time 352ms: Time slice expired; process X preempted with 23ms to go [Q Y Z A B C]
time 356ms: Process Y started using the CPU [Q Z A B C X]
time 440ms: Time slice expired; process Y preempted with 24ms to go [Q Z A B C X]
time 444ms: Process Z started using the CPU [Q A B C X Y]
time 528ms: Time slice expired; process Z preempted with 25ms to go [Q A B C X Y]
time 532ms: Process A started using the CPU with 20ms remaining [Q B C X Y Z]
time 556ms: Process A completed a CPU burst; 3 bursts to go [Q B C X Y Z]
time 556ms: Process A switching out of CPU; will block on I/O until time 760ms [Q B C X Y Z]
time 560ms: Process B started using the CPU with 21ms remaining [Q C X Y Z]
time 585ms: Process B completed a CPU burst; 3 bursts to go [Q C X Y Z]
time 585ms: Process B switching out of CPU; will block on I/O until time 789ms [Q C X Y Z]
time 589ms: Process C started using the CPU with 22ms remaining [Q X Y Z]
time 615ms: Process C completed a CPU burst; 3 bursts to go [Q X Y Z]
time 615ms: Process C switching out of CPU; will block on I/O until time 819ms [Q X Y Z]
time 619ms: Process X started using the CPU with 23ms remaining [Q Y Z]
time 646ms: Process X completed a CPU burst; 3 bursts to go [Q Y Z]
time 646ms: Process X switching out of CPU; will block on I/O until time 850ms [Q Y Z]
time 650ms: Process Y started using the CPU with 24ms remaining [Q Z]
time 678ms: Process Y completed a CPU burst; 3 bursts to go [Q Z]
time 678ms: Process Y switching out of CPU; will block on I/O until time 882ms [Q Z]
time 682ms: Process Z started using the CPU with 25ms remaining [Q <empty>]
time 711ms: Process Z completed a CPU burst; 3 bursts to go [Q <empty>]
time 711ms: Process Z switching out of CPU; will block on I/O until time 915ms [Q <empty>]
time 756ms: Process A completed I/O; added to ready queue [Q A]
time 760ms: Process A started using the CPU [Q <empty>]
time 785ms: Process B completed I/O; added to ready queue [Q B]
time 815ms: Process C completed I/O; added to ready queue [Q B C]
time 844ms: Time slice expired; process A preempted with 20ms to go [Q B C]
time 846ms: Process X completed I/O; added to ready queue [Q C A X]
time 848ms: Process B started using the CPU [Q C A X]
time 878ms: Process Y completed I/O; added to ready queue [Q C A X Y]
time 911ms: Process Z completed I/O; added to ready queue [Q C A X Y Z]
time 932ms: Time slice expired; process B preempted with 21ms to go [Q C A X Y Z]
time 936ms: Process C started using the CPU [Q A X Y Z B]
time 1020ms: Time slice expired; process C preempted with 22ms to go [Q A X Y Z B]
time 1024ms: Process A started using the CPU with 20ms remaining [Q X Y Z B C]
time 1048ms: Process A completed a CPU burst; 2 bursts to go [Q X Y Z B C]
time 1048ms: Process A switching out of CPU; will block on I/O until time 1252ms [Q X Y Z B C]
time 1052ms: Process X started using the CPU [Q Y Z B C]
time 1136ms: Time slice expired; process X preempted with 23ms to go [Q Y Z B C]
time 1140ms: Process Y started using the CPU [Q Z B C X]
time 1224ms: Time slice expired; process Y preempted with 24ms to go [Q Z B C X]
time 1228ms: Process Z started using the CPU [Q B C X Y]
time 1248ms: Process A completed I/O; added to ready queue [Q B C X Y A]
time 1312ms: Time slice expired; process Z preempted with 25ms to go [Q B C X Y A]
time 1316ms: Process B started using the CPU with 21ms remaining [Q C X Y A Z]
time 1341ms: Process B completed a CPU burst; 2 bursts to go [Q C X Y A Z]
time 1341ms: Process B switching out of CPU; will block on I/O until time 1545ms [Q C X Y A Z]
time 1345ms: Process C started using the CPU with 22ms remaining [Q X Y A Z]
time 1371ms: Process C completed a CPU burst; 2 bursts to go [Q X Y A Z]
time 1371ms: Process C switching out of CPU; will block on I/O until time 1575ms [Q X Y A Z]
time 1375ms: Process X started using the CPU with 23ms remaining [Q Y A Z]
time 1402ms: Process X completed a CPU burst; 2 bursts to go [Q Y A Z]
time 1402ms: Process X switching out of CPU; will block on I/O until time 1606ms [Q Y A Z]
time 1406ms: Process Y started using the CPU with 24ms remaining [Q A Z]
time 1434ms: Process Y completed a CPU burst; 2 bursts to go [Q A Z]
time 1434ms: Process Y switching out of CPU; will block on I/O until time 1638ms [Q A Z]
time 1438ms: Process A started using the CPU [Q Z]
time 1522ms: Time slice expired; process A preempted with 20ms to go [Q Z]
time 1526ms: Process Z started using the CPU with 25ms remaining [Q A]
time 1541ms: Process B completed I/O; added to ready queue [Q A B]
time 1555ms: Process Z completed a CPU burst; 2 bursts to go [Q A B]
time 1555ms: Process Z switching out of CPU; will block on I/O until time 1759ms [Q A B]
time 1559ms: Process A started using the CPU with 20ms remaining [Q B]
time 1571ms: Process C completed I/O; added to ready queue [Q B C]
time 1583ms: Process A completed a CPU burst; 1 burst to go [Q B C]
time 1583ms: Process A switching out of CPU; will block on I/O until time 1787ms [Q B C]
time 1587ms: Process B started using the CPU [Q C]
time 1602ms: Process X completed I/O; added to ready queue [Q C X]
time 1634ms: Process Y completed I/O; added to ready queue [Q C X Y]
time 1671ms: Time slice expired; process B preempted with 21ms to go [Q C X Y]
time 1675ms: Process C started using the CPU [Q X Y B]
time 1755ms: Process Z completed I/O; added to ready queue [Q X Y B Z]
time 1759ms: Time slice expired; process C preempted with 22ms to go [Q X Y B Z]
time 1763ms: Process X started using the CPU [Q Y B Z C]
time 1783ms: Process A completed I/O; added to ready queue [Q Y B Z C A]
time 1847ms: Time slice expired; process X preempted with 23ms to go [Q Y B Z C A]
time 1851ms: Process Y started using the CPU [Q B Z C A X]
time 1935ms: Time slice expired; process Y preempted with 24ms to go [Q B Z C A X]
time 1939ms: Process B started using the CPU with 21ms remaining [Q Z C A X Y]
time 1964ms: Process B completed a CPU burst; 1 burst to go [Q Z C A X Y]
time 1964ms: Process B switching out of CPU; will block on I/O until time 2168ms [Q Z C A X Y]
time 1968ms: Process Z started using the CPU [Q C A X Y]
time 2052ms: Time slice expired; process Z preempted with 25ms to go [Q C A X Y]
time 2056ms: Process C started using the CPU with 22ms remaining [Q A X Y Z]
time 2082ms: Process C completed a CPU burst; 1 burst to go [Q A X Y Z]
time 2082ms: Process C switching out of CPU; will block on I/O until time 2286ms [Q A X Y Z]
time 2086ms: Process A started using the CPU [Q X Y Z]
time 2164ms: Process B completed I/O; added to ready queue [Q X Y Z B]
time 2170ms: Time slice expired; process A preempted with 20ms to go [Q X Y Z B]
time 2174ms: Process X started using the CPU with 23ms remaining [Q Y Z B A]
time 2201ms: Process X completed a CPU burst; 1 burst to go [Q Y Z B A]
time 2201ms: Process X switching out of CPU; will block on I/O until time 2405ms [Q Y Z B A]
time 2205ms: Process Y started using the CPU with 24ms remaining [Q Z B A]
time 2233ms: Process Y completed a CPU burst; 1 burst to go [Q Z B A]
time 2233ms: Process Y switching out of CPU; will block on I/O until time 2437ms [Q Z B A]
time 2237ms: Process Z started using the CPU with 25ms remaining [Q B A]
time 2266ms: Process Z completed a CPU burst; 1 burst to go [Q B A]
time 2266ms: Process Z switching out of CPU; will block on I/O until time 2470ms [Q B A]
time 2270ms: Process B started using the CPU [Q A]
time 2282ms: Process C completed I/O; added to ready queue [Q A C]
time 2354ms: Time slice expired; process B preempted with 21ms to go [Q A C]
time 2358ms: Process A started using the CPU with 20ms remaining [Q C B]
time 2382ms: Process A terminated [Q C B]
time 2386ms: Process C started using the CPU [Q B]
time 2401ms: Process X completed I/O; added to ready queue [Q B X]
time 2433ms: Process Y completed I/O; added to ready queue [Q B X Y]
time 2466ms: Process Z completed I/O; added to ready queue [Q B X Y Z]
time 2470ms: Time slice expired; process C preempted with 22ms to go [Q B X Y Z]
time 2474ms: Process B started using the CPU with 21ms remaining [Q X Y Z C]
time 2499ms: Process B terminated [Q X Y Z C]
time 2503ms: Process X started using the CPU [Q Y Z C]
time 2587ms: Time slice expired; process X preempted with 23ms to go [Q Y Z C]
time 2591ms: Process Y started using the CPU [Q Z C X]
time 2675ms: Time slice expired; process Y preempted with 24ms to go [Q Z C X]
time 2679ms: Process Z started using the CPU [Q C X Y]
time 2763ms: Time slice expired; process Z preempted with 25ms to go [Q C X Y]
time 2767ms: Process C started using the CPU with 22ms remaining [Q X Y Z]
time 2793ms: Process C terminated [Q X Y Z]
time 2797ms: Process X started using the CPU with 23ms remaining [Q Y Z]
time 2824ms: Process X terminated [Q Y Z]
time 2828ms: Process Y started using the CPU with 24ms remaining [Q Z]
time 2856ms: Process Y terminated [Q Z]
time 2860ms: Process Z started using the CPU with 25ms remaining [Q <empty>]
time 2889ms: Process Z terminated [Q <empty>]
time 2889ms: Simulator ended for RR
